<robot name="robotics_project" version="1.0">
  <joint name="base_link_joint" type="fixed">
    <origin rpy="0.00000 0.00000 0.00000" xyz="0.00000 0.50000 0.30000"/>
    <parent link="body_link"/>
    <child link="base_link"/>
  </joint>
  <joint name="caster_link_joint" type="fixed">
    <origin rpy="0.00000 0.00000 0.00000" xyz="0.00000 -2.00000 -0.30000"/>
    <parent link="body_link"/>
    <child link="caster_link"/>
  </joint>
  <joint name="gripper_l_link_joint" type="prismatic">
    <limit lower="0.00000" upper="0.20000" effort="0.00000" velocity="0.00000"/>
    <origin rpy="0.00000 0.00000 0.00000" xyz="-0.10000 -0.00000 0.80000"/>
    <parent link="wrist_link"/>
    <child link="gripper_l_link"/>
    <axis xyz="-1.00000 0.00000 0.00000"/>
  </joint>
  <joint name="gripper_r_link_joint" type="prismatic">
    <limit lower="0.00000" upper="0.20000" effort="0.00000" velocity="0.00000"/>
    <origin rpy="0.00000 0.00000 0.00000" xyz="0.10000 -0.00000 0.80000"/>
    <parent link="wrist_link"/>
    <child link="gripper_r_link"/>
    <axis xyz="1.00000 0.00000 0.00000"/>
  </joint>
  <joint name="lower_link_joint" type="continuous">
    <limit lower="0" upper="0" effort="0.00000" velocity="0.00000"/>
    <origin rpy="0.00000 0.00000 0.00000" xyz="0.00000 0.00000 0.40000"/>
    <parent link="base_link"/>
    <child link="lower_link"/>
    <axis xyz="0.00000 0.00000 1.00000"/>
  </joint>
  <joint name="mid_link_joint" type="revolute">
    <limit lower="-2.00000" upper="2.00000" effort="0.00000" velocity="0.00000"/>
    <origin rpy="0.00000 0.00000 0.00000" xyz="-0.00000 -0.00000 1.30000"/>
    <parent link="lower_link"/>
    <child link="mid_link"/>
    <axis xyz="1.00000 0.00000 0.00000"/>
  </joint>
  <joint name="upper_link_joint" type="revolute">
    <limit lower="-2.00000" upper="2.00000" effort="0.00000" velocity="0.00000"/>
    <origin rpy="0.00000 0.00000 0.00000" xyz="0.00000 -0.00000 3.10000"/>
    <parent link="mid_link"/>
    <child link="upper_link"/>
    <axis xyz="1.00000 0.00000 0.00000"/>
  </joint>
  <joint name="wheel_l_link_joint" type="continuous">
    <limit lower="0" upper="0" effort="0.00000" velocity="0.00000"/>
    <origin rpy="0.00000 0.00000 0.00000" xyz="-2.00000 2.00000 0.00000"/>
    <parent link="body_link"/>
    <child link="wheel_l_link"/>
    <axis xyz="-1.00000 0.00000 0.00000"/>
  </joint>
  <joint name="wheel_r_link_joint" type="continuous">
    <limit lower="0" upper="0" effort="0.00000" velocity="0.00000"/>
    <origin rpy="0.00000 0.00000 0.00000" xyz="2.00000 2.00000 0.00000"/>
    <parent link="body_link"/>
    <child link="wheel_r_link"/>
    <axis xyz="1.00000 0.00000 0.00000"/>
  </joint>
  <joint name="wrist_link_joint" type="revolute">
    <limit lower="-2.00000" upper="2.00000" effort="0.00000" velocity="0.00000"/>
    <origin rpy="0.00000 0.00000 0.00000" xyz="0.00000 0.00000 2.80000"/>
    <parent link="upper_link"/>
    <child link="wrist_link"/>
    <axis xyz="1.00000 0.00000 0.00000"/>
  </joint>
  <link name="base_link">
    <collision name="base_1_collision">
      <origin rpy="0.00000 0.00000 0.00000" xyz="0.00000 0.00000 0.10000"/>
      <geometry>
        <mesh filename="package://robotics-project/meshes/stl/base_1.stl" scale="1.00000 1.00000 1.00000"/>
      </geometry>
    </collision>
    <collision name="base_2_collision">
      <origin rpy="0.00000 0.00000 0.00000" xyz="0.00000 0.00000 0.30000"/>
      <geometry>
        <mesh filename="package://robotics-project/meshes/stl/base_2.stl" scale="1.00000 1.00000 1.00000"/>
      </geometry>
    </collision>
    <inertial>
      <inertia ixx="0.00287" ixy="0.00000" ixz="-0.00000" iyy="0.00287" iyz="-0.00000" izz="0.00561"/>
      <origin rpy="0.00000 0.00000 0.00000" xyz="0.00000 0.00000 0.20000"/>
      <mass value="0.02000"/>
    </inertial>
    <visual name="base_1">
      <origin rpy="0.00000 0.00000 0.00000" xyz="0.00000 0.00000 0.10000"/>
      <geometry>
        <mesh filename="package://robotics-project/meshes/stl/base_1.stl" scale="1.00000 1.00000 1.00000"/>
      </geometry>
    </visual>
    <visual name="base_2">
      <origin rpy="0.00000 0.00000 0.00000" xyz="0.00000 0.00000 0.30000"/>
      <geometry>
        <mesh filename="package://robotics-project/meshes/stl/base_2.stl" scale="1.00000 1.00000 1.00000"/>
      </geometry>
    </visual>
  </link>
  <link name="body_link">
    <collision name="body_collision">
      <origin rpy="0.00000 0.00000 0.00000" xyz="0.00000 0.00000 0.00000"/>
      <geometry>
        <box size="4.00000 6.00000 0.60000"/>
      </geometry>
    </collision>
    <inertial>
      <inertia ixx="0.02979" ixy="-0.00000" ixz="0.00000" iyy="0.01342" iyz="-0.00000" izz="0.04261"/>
      <origin rpy="0.00000 0.00000 0.00000" xyz="-0.00000 0.00000 -0.00000"/>
      <mass value="0.01000"/>
    </inertial>
    <visual name="body">
      <origin rpy="0.00000 0.00000 0.00000" xyz="0.00000 0.00000 0.00000"/>
      <geometry>
        <mesh filename="package://robotics-project/meshes/stl/body.stl" scale="1.00000 1.00000 1.00000"/>
      </geometry>
    </visual>
  </link>
  <link name="caster_link">
    <collision name="caster_collision">
      <origin rpy="0.00000 0.00000 0.00000" xyz="0.00000 0.00000 0.00000"/>
      <geometry>
        <sphere radius="0.51961"/>
      </geometry>
    </collision>
    <inertial>
      <inertia ixx="0.00099" ixy="-0.00000" ixz="0.00000" iyy="0.00099" iyz="-0.00000" izz="0.00099"/>
      <origin rpy="0.00000 0.00000 0.00000" xyz="0.00000 0.00000 0.00000"/>
      <mass value="0.01000"/>
    </inertial>
    <visual name="caster">
      <origin rpy="0.00000 0.00000 0.00000" xyz="0.00000 0.00000 0.00000"/>
      <geometry>
        <mesh filename="package://robotics-project/meshes/stl/caster.stl" scale="1.00000 1.00000 1.00000"/>
      </geometry>
    </visual>
  </link>
  <link name="gripper_l_link">
    <collision name="gripper_l_collision">
      <origin rpy="0.00000 0.00000 0.00000" xyz="-0.00000 0.00000 0.40000"/>
      <geometry>
        <mesh filename="package://robotics-project/meshes/stl/gripper_l.stl" scale="1.00000 1.00000 1.00000"/>
      </geometry>
    </collision>
    <inertial>
      <inertia ixx="0.00067" ixy="-0.00000" ixz="-0.00000" iyy="0.00057" iyz="0.00000" izz="0.00017"/>
      <origin rpy="0.00000 0.00000 0.00000" xyz="0.00000 0.00000 0.40000"/>
      <mass value="0.01000"/>
    </inertial>
    <visual name="gripper_l">
      <origin rpy="0.00000 0.00000 0.00000" xyz="0.00000 0.00000 0.40000"/>
      <geometry>
        <mesh filename="package://robotics-project/meshes/stl/gripper_l.stl" scale="1.00000 1.00000 1.00000"/>
      </geometry>
    </visual>
  </link>
  <link name="gripper_r_link">
    <collision name="gripper_r_collision">
      <origin rpy="0.00000 0.00000 0.00000" xyz="-0.00000 0.00000 0.40000"/>
      <geometry>
        <mesh filename="package://robotics-project/meshes/stl/gripper_r.stl" scale="1.00000 1.00000 1.00000"/>
      </geometry>
    </collision>
    <inertial>
      <inertia ixx="0.00067" ixy="-0.00000" ixz="-0.00000" iyy="0.00057" iyz="0.00000" izz="0.00017"/>
      <origin rpy="0.00000 0.00000 0.00000" xyz="0.00000 0.00000 0.40000"/>
      <mass value="0.01000"/>
    </inertial>
    <visual name="gripper_r">
      <origin rpy="0.00000 0.00000 0.00000" xyz="0.00000 0.00000 0.40000"/>
      <geometry>
        <mesh filename="package://robotics-project/meshes/stl/gripper_r.stl" scale="1.00000 1.00000 1.00000"/>
      </geometry>
    </visual>
  </link>
  <link name="lower_link">
    <collision name="lower_collision">
      <origin rpy="0.00000 0.00000 0.00000" xyz="0.00000 0.00000 1.00000"/>
      <geometry>
        <mesh filename="package://robotics-project/meshes/stl/lower.stl" scale="1.00000 1.00000 1.00000"/>
      </geometry>
    </collision>
    <inertial>
      <inertia ixx="0.00816" ixy="0.00000" ixz="-0.00000" iyy="0.00867" iyz="-0.00000" izz="0.00289"/>
      <origin rpy="0.00000 0.00000 0.00000" xyz="0.00000 0.00000 0.68757"/>
      <mass value="0.01000"/>
    </inertial>
    <visual name="lower">
      <origin rpy="0.00000 0.00000 0.00000" xyz="0.00000 0.00000 1.00000"/>
      <geometry>
        <mesh filename="package://robotics-project/meshes/stl/lower.stl" scale="1.00000 1.00000 1.00000"/>
      </geometry>
    </visual>
  </link>
  <link name="mid_link">
    <collision name="mid_collision">
      <origin rpy="0.00000 0.00000 0.00000" xyz="0.00000 0.00000 0.90000"/>
      <geometry>
        <mesh filename="package://robotics-project/meshes/stl/mid.stl" scale="1.00000 1.00000 1.00000"/>
      </geometry>
    </collision>
    <collision name="mid_l_collision">
      <origin rpy="0.00000 0.00000 0.00000" xyz="-0.60000 -0.00000 2.40000"/>
      <geometry>
        <mesh filename="package://robotics-project/meshes/stl/mid_l.stl" scale="1.00000 1.00000 1.00000"/>
      </geometry>
    </collision>
    <collision name="mid_r_collision">
      <origin rpy="0.00000 0.00000 0.00000" xyz="0.60000 -0.00000 2.40000"/>
      <geometry>
        <mesh filename="package://robotics-project/meshes/stl/mid_r.stl" scale="1.00000 1.00000 1.00000"/>
      </geometry>
    </collision>
    <inertial>
      <inertia ixx="0.01675" ixy="-0.00000" ixz="0.00000" iyy="0.01425" iyz="0.00000" izz="0.00429"/>
      <origin rpy="0.00000 0.00000 0.00000" xyz="-0.00000 -0.00000 1.90000"/>
      <mass value="0.03000"/>
    </inertial>
    <visual name="mid">
      <origin rpy="0.00000 0.00000 0.00000" xyz="0.00000 0.00000 0.90000"/>
      <geometry>
        <mesh filename="package://robotics-project/meshes/stl/mid.stl" scale="1.00000 1.00000 1.00000"/>
      </geometry>
    </visual>
    <visual name="mid_l">
      <origin rpy="0.00000 0.00000 0.00000" xyz="-0.60000 -0.00000 2.40000"/>
      <geometry>
        <mesh filename="package://robotics-project/meshes/stl/mid_l.stl" scale="1.00000 1.00000 1.00000"/>
      </geometry>
    </visual>
    <visual name="mid_r">
      <origin rpy="0.00000 0.00000 0.00000" xyz="0.60000 -0.00000 2.40000"/>
      <geometry>
        <mesh filename="package://robotics-project/meshes/stl/mid_r.stl" scale="1.00000 1.00000 1.00000"/>
      </geometry>
    </visual>
  </link>
  <link name="upper_link">
    <collision name="upper_collision">
      <origin rpy="0.00000 0.00000 0.00000" xyz="-0.00000 0.00000 1.20000"/>
      <geometry>
        <mesh filename="package://robotics-project/meshes/stl/upper.stl" scale="1.00000 1.00000 1.00000"/>
      </geometry>
    </collision>
    <inertial>
      <inertia ixx="0.01405" ixy="-0.00000" ixz="-0.00000" iyy="0.01386" iyz="0.00000" izz="0.00198"/>
      <origin rpy="0.00000 0.00000 0.00000" xyz="-0.00000 0.00000 0.96137"/>
      <mass value="0.01000"/>
    </inertial>
    <visual name="upper">
      <origin rpy="0.00000 0.00000 0.00000" xyz="0.00000 0.00000 1.20000"/>
      <geometry>
        <mesh filename="package://robotics-project/meshes/stl/upper.stl" scale="1.00000 1.00000 1.00000"/>
      </geometry>
    </visual>
  </link>
  <link name="wheel_l_link">
    <collision name="wheel_l_collision">
      <origin rpy="-0.00000 1.57080 0.00000" xyz="-0.20000 0.00000 0.00000"/>
      <geometry>
        <cylinder radius="0.80000" length="0.40000"/>
      </geometry>
    </collision>
    <inertial>
      <inertia ixx="0.00318" ixy="0.00000" ixz="0.00000" iyy="0.00172" iyz="0.00000" izz="0.00172"/>
      <origin rpy="0.00000 0.00000 0.00000" xyz="-0.20000 0.00000 0.00000"/>
      <mass value="0.01000"/>
    </inertial>
    <visual name="wheel_l">
      <origin rpy="0.00000 0.00000 0.00000" xyz="-0.20000 0.00000 0.00000"/>
      <geometry>
        <mesh filename="package://robotics-project/meshes/stl/wheel_l.stl" scale="1.00000 1.00000 1.00000"/>
      </geometry>
    </visual>
  </link>
  <link name="wheel_r_link">
    <collision name="wheel_r_collision">
      <origin rpy="-0.00000 1.57080 0.00000" xyz="0.20000 0.00000 0.00000"/>
      <geometry>
        <cylinder radius="0.80000" length="0.40000"/>
      </geometry>
    </collision>
    <inertial>
      <inertia ixx="0.00318" ixy="0.00000" ixz="0.00000" iyy="0.00172" iyz="0.00000" izz="0.00172"/>
      <origin rpy="0.00000 0.00000 0.00000" xyz="0.20000 0.00000 0.00000"/>
      <mass value="0.01000"/>
    </inertial>
    <visual name="wheel_r">
      <origin rpy="0.00000 0.00000 0.00000" xyz="0.20000 0.00000 0.00000"/>
      <geometry>
        <mesh filename="package://robotics-project/meshes/stl/wheel_r.stl" scale="1.00000 1.00000 1.00000"/>
      </geometry>
    </visual>
  </link>
  <link name="wrist_link">
    <collision name="wrist_collision">
      <origin rpy="0.00000 0.00000 0.00000" xyz="-0.00000 0.00000 0.10000"/>
      <geometry>
        <mesh filename="package://robotics-project/meshes/stl/attach.stl" scale="1.00000 1.00000 1.00000"/>
      </geometry>
    </collision>
    <inertial>
      <inertia ixx="0.00271" ixy="0.00000" ixz="-0.00000" iyy="0.00251" iyz="0.00000" izz="0.00080"/>
      <origin rpy="0.00000 0.00000 0.00000" xyz="0.00000 -0.00000 0.22890"/>
      <mass value="0.01000"/>
    </inertial>
    <visual name="wrist">
      <origin rpy="0.00000 0.00000 0.00000" xyz="0.00000 -0.00000 0.10000"/>
      <geometry>
        <mesh filename="package://robotics-project/meshes/stl/attach.stl" scale="1.00000 1.00000 1.00000"/>
      </geometry>
    </visual>
  </link>
</robot>
