<robot name="robot" version="1.0">
  <joint name="arm_base_link_joint" type="fixed">
    <origin rpy="0.00000 0.00000 0.00000" xyz="0.00000 0.00000 0.10000"/>
    <parent link="base_body_link"/>
    <child link="arm_base_link"/>
  </joint>
  <joint name="arm_lower_link_joint" type="revolute">
    <limit lower="-3.14000" upper="3.14000" effort="0.00000" velocity="0.00000"/>
    <origin rpy="0.00000 0.00000 0.00000" xyz="0.00000 0.00000 0.03000"/>
    <parent link="arm_base_link"/>
    <child link="arm_lower_link"/>
    <axis xyz="0.00000 0.00000 1.00000"/>
  </joint>
  <joint name="arm_mid_link_joint" type="revolute">
    <limit lower="-1.57080" upper="1.57080" effort="0.00000" velocity="0.00000"/>
    <origin rpy="0.00000 0.00000 0.00000" xyz="0.00000 -0.00000 0.09000"/>
    <parent link="arm_lower_link"/>
    <child link="arm_mid_link"/>
    <axis xyz="1.00000 0.00000 0.00000"/>
  </joint>
  <joint name="arm_upper_link_joint" type="revolute">
    <limit lower="-2.18166" upper="2.18166" effort="0.00000" velocity="0.00000"/>
    <origin rpy="0.00000 0.00000 0.00000" xyz="0.00000 0.00000 0.36000"/>
    <parent link="arm_mid_link"/>
    <child link="arm_upper_link"/>
    <axis xyz="1.00000 0.00000 0.00000"/>
  </joint>
  <joint name="arm_wrist_link_joint" type="revolute">
    <limit lower="-1.57080" upper="1.57080" effort="0.00000" velocity="0.00000"/>
    <origin rpy="0.00000 0.00000 -0.00000" xyz="0.00000 0.00000 0.21000"/>
    <parent link="arm_upper_link"/>
    <child link="arm_wrist_link"/>
    <axis xyz="1.00000 0.00000 0.00000"/>
  </joint>
  <joint name="base_caster_link_joint" type="fixed">
    <origin rpy="0.00000 0.00000 0.00000" xyz="0.00000 -0.12000 -0.09000"/>
    <parent link="base_body_link"/>
    <child link="base_caster_link"/>
  </joint>
  <joint name="base_wheel_l_link_joint" type="continuous">
    <limit lower="0.00000" upper="0.00000" effort="0.00000" velocity="0.00000"/>
    <origin rpy="0.00000 0.00000 0.00000" xyz="-0.22000 0.10000 -0.05000"/>
    <parent link="base_body_link"/>
    <child link="base_wheel_l_link"/>
    <axis xyz="-1.00000 0.00000 0.00000"/>
  </joint>
  <joint name="base_wheel_r_link_joint" type="continuous">
    <limit lower="0.00000" upper="0.00000" effort="0.00000" velocity="0.00000"/>
    <origin rpy="0.00000 0.00000 0.00000" xyz="0.22000 0.10000 -0.05000"/>
    <parent link="base_body_link"/>
    <child link="base_wheel_r_link"/>
    <axis xyz="1.00000 0.00000 0.00000"/>
  </joint>
  <joint name="gripper_base_link_joint" type="fixed">
    <origin rpy="-0.00000 0.00000 0.00000" xyz="-0.00000 0.00000 0.07000"/>
    <parent link="arm_wrist_link"/>
    <child link="gripper_base_link"/>
  </joint>
  <joint name="gripper_l_link_joint" type="prismatic">
    <limit lower="-0.25000" upper="0.00000" effort="0.00000" velocity="0.00000"/>
    <origin rpy="-0.00000 0.00000 0.00000" xyz="-0.04000 -0.00000 0.05000"/>
    <parent link="gripper_base_link"/>
    <child link="gripper_l_link"/>
    <axis xyz="-1.00000 0.00000 0.00000"/>
  </joint>
  <joint name="gripper_r_link_joint" type="prismatic">
    <limit lower="-0.25000" upper="0.00000" effort="0.00000" velocity="0.00000"/>
    <origin rpy="-0.00000 0.00000 0.00000" xyz="0.04000 -0.00000 0.05000"/>
    <parent link="gripper_base_link"/>
    <child link="gripper_r_link"/>
    <axis xyz="1.00000 0.00000 0.00000"/>
  </joint>
  <link name="arm_base_link">
    <collision name="arm_base_collision">
      <origin rpy="0.00000 0.00000 0.00000" xyz="0.00000 0.00000 0.00000"/>
      <geometry>
        <cylinder radius="0.05000" length="0.02000"/>
      </geometry>
    </collision>
    <inertial>
      <inertia ixx="0.03292" ixy="0.00000" ixz="0.00000" iyy="0.03292" iyz="0.00000" izz="0.06250"/>
      <origin rpy="0.00000 0.00000 0.00000" xyz="0.00000 0.00000 0.00000"/>
      <mass value="0.50000"/>
    </inertial>
    <visual name="arm_base">
      <origin rpy="0.00000 0.00000 0.00000" xyz="0.00000 0.00000 0.00000"/>
      <geometry>
        <mesh filename="file://$(find robotics-project)/meshes/stl/arm_base.stl" scale="0.10000 0.10000 0.10000"/>
      </geometry>
    </visual>
  </link>
  <link name="arm_lower_link">
    <collision name="arm_lower_collision">
      <origin rpy="0.00000 0.00000 0.00000" xyz="0.00000 0.00000 0.07000"/>
      <geometry>
        <box size="0.16000 0.16000 0.18000"/>
      </geometry>
    </collision>
    <inertial>
      <inertia ixx="0.48333" ixy="0.00000" ixz="0.00000" iyy="0.48333" iyz="0.00000" izz="0.42667"/>
      <origin rpy="0.00000 0.00000 0.00000" xyz="0.00000 0.00000 0.70000"/>
      <mass value="1.00000"/>
    </inertial>
    <visual name="arm_lower">
      <origin rpy="0.00000 0.00000 0.00000" xyz="0.00000 0.00000 0.00000"/>
      <geometry>
        <mesh filename="file://$(find robotics-project)/meshes/stl/arm_lower.stl" scale="0.10000 0.10000 0.10000"/>
      </geometry>
    </visual>
  </link>
  <link name="arm_mid_link">
    <collision name="arm_mid_collision">
      <origin rpy="0.00000 0.00000 0.00000" xyz="0.00000 0.00000 0.18000"/>
      <geometry>
        <box size="0.16000 0.12000 0.46000"/>
      </geometry>
    </collision>
    <inertial>
      <inertia ixx="1.88333" ixy="0.00000" ixz="0.00000" iyy="1.97667" iyz="0.00000" izz="0.33333"/>
      <origin rpy="0.00000 0.00000 0.00000" xyz="0.00000 0.00000 1.80000"/>
      <mass value="1.00000"/>
    </inertial>
    <visual name="arm_mid">
      <origin rpy="0.00000 0.00000 0.00000" xyz="0.00000 0.00000 -0.00000"/>
      <geometry>
        <mesh filename="file://$(find robotics-project)/meshes/stl/arm_mid.stl" scale="0.10000 0.10000 0.10000"/>
      </geometry>
    </visual>
  </link>
  <link name="arm_upper_link">
    <collision name="arm_upper_collision">
      <origin rpy="0.00000 0.00000 -0.00000" xyz="-0.00000 -0.00000 0.10500"/>
      <geometry>
        <box size="0.08000 0.08000 0.29000"/>
      </geometry>
    </collision>
    <inertial>
      <inertia ixx="0.56563" ixy="0.00000" ixz="0.00000" iyy="0.56563" iyz="0.00000" izz="0.08000"/>
      <origin rpy="0.00000 0.00000 0.00000" xyz="-0.00000 -0.00000 1.05000"/>
      <mass value="0.75000"/>
    </inertial>
    <visual name="arm_upper">
      <origin rpy="0.00000 0.00000 -0.00000" xyz="-0.00000 0.00000 -0.00000"/>
      <geometry>
        <mesh filename="file://$(find robotics-project)/meshes/stl/arm_upper.stl" scale="0.10000 0.10000 0.10000"/>
      </geometry>
    </visual>
  </link>
  <link name="arm_wrist_link">
    <collision name="arm_wrist_collision">
      <origin rpy="-0.00000 0.00000 0.00000" xyz="-0.00000 -0.00000 0.01000"/>
      <geometry>
        <box size="0.04000 0.08000 0.10000"/>
      </geometry>
    </collision>
    <inertial>
      <inertia ixx="0.05125" ixy="0.00000" ixz="0.00000" iyy="0.03625" iyz="0.00000" izz="0.02500"/>
      <origin rpy="0.00000 0.00000 0.00000" xyz="-0.00000 -0.00000 0.10000"/>
      <mass value="0.37500"/>
    </inertial>
    <visual name="arm_wrist">
      <origin rpy="-0.00000 0.00000 0.00000" xyz="-0.00000 0.00000 0.00000"/>
      <geometry>
        <mesh filename="file://$(find robotics-project)/meshes/stl/arm_wrist.stl" scale="0.10000 0.10000 0.10000"/>
      </geometry>
    </visual>
  </link>
  <link name="base_body_link">
    <collision name="base_body_collision">
      <origin rpy="0.00000 0.00000 0.00000" xyz="0.00000 0.00000 0.00000"/>
      <geometry>
        <box size="0.40000 0.40000 0.18000"/>
      </geometry>
    </collision>
    <inertial>
      <inertia ixx="8.01667" ixy="0.00000" ixz="0.00000" iyy="8.01667" iyz="0.00000" izz="13.33333"/>
      <origin rpy="0.00000 0.00000 0.00000" xyz="0.00000 0.00000 0.00000"/>
      <mass value="5.00000"/>
    </inertial>
    <visual name="base_body">
      <origin rpy="0.00000 0.00000 0.00000" xyz="0.00000 0.00000 0.00000"/>
      <geometry>
        <mesh filename="file://$(find robotics-project)/meshes/stl/base_body.stl" scale="0.10000 0.10000 0.10000"/>
      </geometry>
    </visual>
  </link>
  <link name="base_caster_link">
    <collision name="base_caster_collision">
      <origin rpy="0.00000 0.00000 0.00000" xyz="0.00000 0.00000 0.00000"/>
      <geometry>
        <sphere radius="0.06235"/>
      </geometry>
    </collision>
    <inertial>
      <inertia ixx="0.01555" ixy="0.00000" ixz="0.00000" iyy="0.01555" iyz="0.00000" izz="0.01555"/>
      <origin rpy="0.00000 0.00000 0.00000" xyz="0.00000 0.00000 0.00000"/>
      <mass value="0.10000"/>
    </inertial>
    <visual name="base_caster">
      <origin rpy="0.00000 0.00000 0.00000" xyz="0.00000 0.00000 0.00000"/>
      <geometry>
        <mesh filename="file://$(find robotics-project)/meshes/stl/base_caster.stl" scale="0.10000 0.10000 0.10000"/>
      </geometry>
    </visual>
  </link>
  <link name="base_wheel_l_link">
    <collision name="base_wheel_l_collision">
      <origin rpy="-0.00000 1.57080 0.00000" xyz="0.00000 0.00000 0.00000"/>
      <geometry>
        <cylinder radius="0.10000" length="0.04000"/>
      </geometry>
    </collision>
    <inertial>
      <inertia ixx="0.05000" ixy="0.00000" ixz="0.00000" iyy="0.02633" iyz="0.00000" izz="0.02633"/>
      <origin rpy="0.00000 0.00000 0.00000" xyz="0.00000 0.00000 0.00000"/>
      <mass value="0.10000"/>
    </inertial>
    <visual name="base_wheel_l">
      <origin rpy="0.00000 0.00000 0.00000" xyz="0.00000 0.00000 0.00000"/>
      <geometry>
        <mesh filename="file://$(find robotics-project)/meshes/stl/base_wheel_l.stl" scale="0.10000 0.10000 0.10000"/>
      </geometry>
    </visual>
  </link>
  <link name="base_wheel_r_link">
    <collision name="base_wheel_r_collision">
      <origin rpy="-0.00000 1.57080 0.00000" xyz="-0.00000 0.00000 0.00000"/>
      <geometry>
        <cylinder radius="0.10000" length="0.04000"/>
      </geometry>
    </collision>
    <inertial>
      <inertia ixx="0.05000" ixy="0.00000" ixz="0.00000" iyy="0.02633" iyz="0.00000" izz="0.02633"/>
      <origin rpy="0.00000 0.00000 0.00000" xyz="0.00000 0.00000 0.00000"/>
      <mass value="0.10000"/>
    </inertial>
    <visual name="base_wheel_r">
      <origin rpy="0.00000 0.00000 0.00000" xyz="-0.00000 0.00000 0.00000"/>
      <geometry>
        <mesh filename="file://$(find robotics-project)/meshes/stl/base_wheel_r.stl" scale="0.10000 0.10000 0.10000"/>
      </geometry>
    </visual>
  </link>
  <link name="gripper_base_link">
    <collision name="gripper_base_collision">
      <origin rpy="-0.00000 0.00000 0.00000" xyz="-0.00000 -0.00000 0.00000"/>
      <geometry>
        <box size="0.10000 0.04000 0.02000"/>
      </geometry>
    </collision>
    <inertial>
      <inertia ixx="0.00104" ixy="0.00000" ixz="0.00000" iyy="0.00542" iyz="-0.00000" izz="0.00604"/>
      <origin rpy="0.00000 0.00000 0.00000" xyz="0.00000 -0.00000 0.00000"/>
      <mass value="0.06250"/>
    </inertial>
    <visual name="gripper_base">
      <origin rpy="-0.00000 0.00000 0.00000" xyz="-0.00000 -0.00000 0.00000"/>
      <geometry>
        <mesh filename="file://$(find robotics-project)/meshes/stl/gripper_base.stl" scale="0.10000 0.10000 0.10000"/>
      </geometry>
    </visual>
  </link>
  <link name="gripper_l_link">
    <collision name="gripper_l_collision">
      <origin rpy="-0.00000 0.00000 0.00000" xyz="0.00000 -0.00000 0.00000"/>
      <geometry>
        <box size="0.02000 0.04000 0.08000"/>
      </geometry>
    </collision>
    <inertial>
      <inertia ixx="0.00417" ixy="0.00000" ixz="0.00000" iyy="0.00354" iyz="0.00000" izz="0.00104"/>
      <origin rpy="0.00000 0.00000 0.00000" xyz="0.00000 -0.00000 0.00000"/>
      <mass value="0.06250"/>
    </inertial>
    <visual name="gripper_l">
      <origin rpy="-0.00000 0.00000 0.00000" xyz="0.00000 -0.00000 0.00000"/>
      <geometry>
        <mesh filename="file://$(find robotics-project)/meshes/stl/gripper_l.stl" scale="0.10000 0.10000 0.10000"/>
      </geometry>
    </visual>
  </link>
  <link name="gripper_r_link">
    <collision name="gripper_r_collision">
      <origin rpy="-0.00000 0.00000 0.00000" xyz="-0.00000 -0.00000 0.00000"/>
      <geometry>
        <box size="0.02000 0.04000 0.08000"/>
      </geometry>
    </collision>
    <inertial>
      <inertia ixx="0.00417" ixy="0.00000" ixz="0.00000" iyy="0.00354" iyz="0.00000" izz="0.00104"/>
      <origin rpy="0.00000 0.00000 0.00000" xyz="0.00000 -0.00000 0.00000"/>
      <mass value="0.06250"/>
    </inertial>
    <visual name="gripper_r">
      <origin rpy="-0.00000 0.00000 0.00000" xyz="-0.00000 -0.00000 0.00000"/>
      <geometry>
        <mesh filename="file://$(find robotics-project)/meshes/stl/gripper_r.stl" scale="0.10000 0.10000 0.10000"/>
      </geometry>
    </visual>
  </link>
</robot>
